Workbook
Name A: 'Daten und Kennfelder'!$B$5
Name A_Motorrad: '6 Schwerpunkt '!$E$12
Name ay: '5 Einspur'!$F$34
Name C_ah: 'Daten und Kennfelder'!$L$5
Name C_av: 'Daten und Kennfelder'!$L$4
Name cw: 'Daten und Kennfelder'!$B$8
Name cw_motorrad: '6 Schwerpunkt '!$E$11
Name e_3: '4 Fahrleistung'!$C$31
Name e_5: '4 Fahrleistung'!$C$31
Name eta_Tr: 'Daten und Kennfelder'!$D$12
Name F_lW_Motorrad: '6 Schwerpunkt '!$G$42
Name FG_Motorrad: '6 Schwerpunkt '!$G$41
Name fr: 'Daten und Kennfelder'!$B$7
Name g_Erdbeschl.: 'Daten und Kennfelder'!$S$9
Name G_normal_Gewichtskr.: '6 Schwerpunkt '!$G$41
Name G_normal_Gewichtskr.: '7 Schwerpunkt'!$G$49
Name H_Heizwert_Diesel: 'Daten und Kennfelder'!$G$16
Name h_LW: '7 Schwerpunkt'!$D$32
Name h_LW: 'Daten und Kennfelder'!$D$8
Name h_LW_Motorrad: '6 Schwerpunkt '!$C$11
Name h_s: 'Daten und Kennfelder'!$D$6
Name h_s_Motorrad: '6 Schwerpunkt '!$C$12
Name hs: 'Daten und Kennfelder'!$D$6
Name I_1: Getriebeauslegung!$M$46
Name I_2: Getriebeauslegung!$M$50
Name I_3: Getriebeauslegung!$M$49
Name I_4: Getriebeauslegung!$M$48
Name I_5: 'Daten und Kennfelder'!$B$16
Name i_Achse: 'Daten und Kennfelder'!$B$19
Name J_Getr: 'Daten und Kennfelder'!$D$19
Name J_Kuppl: 'Daten und Kennfelder'!$D$18
Name J_Motor: 'Daten und Kennfelder'!$D$17
Name J_Rad: 'Daten und Kennfelder'!$D$15
Name J_red: '4 Fahrleistung'!$D$23
Name J_Triebstrang: 'Daten und Kennfelder'!$D$16
Name l_0: 'Daten und Kennfelder'!$D$4
Name l_0_Motorrad: '6 Schwerpunkt '!$C$13
Name l_h_Motorrad: '6 Schwerpunkt '!$C$14
Name LambdaA: Nebenrechnung_5!$E$34
Name LambdaA: ' 2 Fahrwiderst'!$E$34
Name lh: 'Daten und Kennfelder'!$D$5
Name m_F_normal: 'Daten und Kennfelder'!$B$4
Name M_max: 'Daten und Kennfelder'!$I$4
Name m_Motorrad: '6 Schwerpunkt '!$E$14
Name Mue: 'Daten und Kennfelder'!$L$6
Name n_4800: 'Daten und Kennfelder'!$G$11
Name n_max: 'Daten und Kennfelder'!$G$13
Name n_nenn: 'Daten und Kennfelder'!$G$5
Name p: Nebenrechnung_5!$E$13
Name p: ' 2 Fahrwiderst'!$E$13
Name P_B: '4 Fahrleistung'!$E$35
Name P_nenn: 'Daten und Kennfelder'!$G$4
Name P_S: Nebenrechnung_5!$D$66
Name P_S: ' 2 Fahrwiderst'!$D$66
Name P_ü: '4 Fahrleistung'!$F$17
Name phi_2: Getriebeauslegung!$M$41
Name Radius: '5 Einspur'!$F$21
Name rdyn: 'Daten und Kennfelder'!$B$6
Name roh_Kraftst.: 'Daten und Kennfelder'!$I$15
Name roh_Luft: 'Daten und Kennfelder'!$G$15

Sheet Deckblatt

Sheet Daten und Kennfelder
A1: Datenblatt eines Fahrzeuges mit Ottomotor
A3: Fahrzeug | F3: Motor/Kupplung | K3: Reifen | Q3: Nebenrechnungen
A4: mF= | B4: 1300 | C4: Radstand lo = | D4: 2.8 | F4: Pnenn = | G4: =I12 -> 111.1053 | H4: Mmax = | I4: 202 | K4: Cav = | L4: 50000
A5: A= | B5: 2.4 | C5: lh = | D5: 1.6 | F5: nnenn = | G5: =G12 -> 5500 | H5: n(max) = | I5: =n_max -> 6100 | K5: Cah = | L5: 60000 | R5: lh = | S5: =lh -> 1.6
A6: r dyn = | B6: 0.32 | C6: hs = | D6: 0.6 | K6: μ = | L6: 1.06 | R6: lv = | S6: =D4-S5 -> 1.2
A7: f R = | B7: 0.01 | C7: Spurweite s = | D7: 1.6 | G7: Volllastkennlinie des Motors | R7: hS = | S7: =hs -> 0.6
A8: c W = | B8: 0.3 | F8: n = | G8: 900 | H8: 120 | I8: =H8*G8/9554 -> 11.304166 | U8: =1000/(2*PI()/60) -> 9549.2966
F9: n = | G9: 1500 | H9: 165 | I9: =H9*G9/9554 -> 25.90538 | R9: g = | S9: 9.81
F10: n = | G10: 3000 | H10: 198 | I10: =H10*G10/9554 -> 62.172912
A11: Antriebsstrang (Getriebe und Antriebsachse) | F11: n = | G11: 4800 | H11: 200 | I11: =H11*G11/9554 -> 100.48147 | Q11: Höchstgeschwindigkeit
A12: i1 = | B12: =I_1 -> 4.8006611 | C12: ηtr (Triebstrang) = | D12: 0.94 | F12: n = | G12: 5500 | H12: 193 | I12: =H12*G12/9554 -> 111.1053
A13: i2 = | B13: =I_2 -> 2.4871474 | F13: nmax = | G13: 6100 | H13: 160 | I13: =H13*G13/9554 -> 102.15616 | K13: Hinweis:
A14: i3 = | B14: =I_3 -> 1.481835 | F14: Luft/Kraftstoff
A15: i4 = | B15: =I_4 -> 1.0153038 | C15: JR (je Rad) = | D15: 2.5 | F15: ρLuft = | G15: 1.18 | H15: ρKraftst = | I15: 0.8
A16: i5 = | B16: 0.8 | C16: JAntr (Antriebst.) = | D16: 0.1 | F16: H = | G16: 40
C17: JM (Motor) = | D17: 0.3
A18: iG_ges= | B18: {=I_1/I_5} -> 6.0008264 | C18: Jk (Kupplung) = | D18: 0.1
A19: iAchse = | B19: 3.46 | C19: JG (Getriebe) = | D19: 0.15
T25: p = | U25: =(2*m_F_normal*g_Erdbeschl.*fr)/(cw*A*roh_Luft) -> 300.21186
T28: q = | U28: =-(2*P_nenn*1000*eta_A*eta_G)/(cw*A*roh_Luft) -> #NAME?
T32: a1 = | U32: =(-U28/2+SQRT((U28/2)^2+(U25/3)^3))^(1/3) -> #NAME?
T36: a2 = | U36: =(-U28/2-SQRT((U28/2)^2+(U25/3)^3))^(1/3) -> #NAME?
T39: v = | U39: =U32+U36 -> #NAME?
U40: =U39*3.6 -> #NAME?
O44: 200 | P44: 200b | Q44: 250 | R44: 250b | AB44: 111 | AC44: 100 | AD44: 90 | AE44: 80 | AF44: 70 | AG44: 60 | AH44: 50 | AI44: 40 | AJ44: 30 | AK44: 20 | AL44: 10 | AM44: 5
N45: 800 | T45: 120 | U45: 85 | V45: 52 | W45: =T45+5 -> 125 | AA45: 800 | AB45: =AB$44/$AA45*9554 -> 1325.6175 | AC45: =AC$44/$AA45*9554 -> 1194.25 | AD45: =AD$44/$AA45*9554 -> 1074.825 | AE45: =AE$44/$AA45*9554 -> 955.4 | AF45: =AF$44/$AA45*9554 -> 835.975 | AG45: =AG$44/$AA45*9554 -> 716.55 | AH45: =AH$44/$AA45*9554 -> 597.125 | AI45: =AI$44/$AA45*9554 -> 477.7 | ... AM45: =AM$44/$AA45*9554 -> 59.7125 | AS45: 120 | AT45: 85 | AU45: 52 | AV45: =AS45+5 -> 125
N46: 1000 | T46: 110 | U46: 79 | V46: 50 | W46: =T46+5 -> 115 | AA46: 1000 | AB46: =AB$44/$AA46*9554 -> 1060.494 | AC46: =AC$44/$AA46*9554 -> 955.4 | AD46: =AD$44/$AA46*9554 -> 859.86 | AE46: =AE$44/$AA46*9554 -> 764.32 | AF46: =AF$44/$AA46*9554 -> 668.78 | AG46: =AG$44/$AA46*9554 -> 573.24 | AH46: =AH$44/$AA46*9554 -> 477.7 | AI46: =AI$44/$AA46*9554 -> 382.16 | ... AM46: =AM$44/$AA46*9554 -> 47.77 | AS46: 110 | AT46: 79 | AU46: 50 | AV46: =AS46+5 -> 115
N47: 1200 | T47: 105 | U47: 75 | V47: 47 | W47: =T47+5 -> 110 | AA47: 1200 | AB47: =AB$44/$AA47*9554 -> 883.745 | AC47: =AC$44/$AA47*9554 -> 796.16667 | AD47: =AD$44/$AA47*9554 -> 716.55 | AE47: =AE$44/$AA47*9554 -> 636.93333 | AF47: =AF$44/$AA47*9554 -> 557.31667 | AG47: =AG$44/$AA47*9554 -> 477.7 | AH47: =AH$44/$AA47*9554 -> 398.08333 | AI47: =AI$44/$AA47*9554 -> 318.46667 | ... AM47: =AM$44/$AA47*9554 -> 39.808333 | AR47: 150 | AS47: 105 | AT47: 75 | AU47: 47 | AV47: =AS47+5 -> 110
N48: 1400 | S48: 160 | T48: 102 | U48: 72 | V48: 46 | W48: =T48+5 -> 107 | AA48: 1400 | AB48: =AB$44/$AA48*9554 -> 757.49571 | AC48: =AC$44/$AA48*9554 -> 682.42857 | AD48: =AD$44/$AA48*9554 -> 614.18571 | AE48: =AE$44/$AA48*9554 -> 545.94286 | AF48: =AF$44/$AA48*9554 -> 477.7 | AG48: =AG$44/$AA48*9554 -> 409.45714 | AH48: =AH$44/$AA48*9554 -> 341.21429 | AI48: =AI$44/$AA48*9554 -> 272.97143 | ... AM48: =AM$44/$AA48*9554 -> 34.121429 | AR48: 135 | AS48: 102 | AT48: 72 | AU48: 46 | AV48: =AS48+5 -> 107
N49: 1600 | S49: 132 | T49: 99 | U49: 71 | V49: 45 | W49: =T49+5 -> 104 | AA49: 1600 | AB49: =AB$44/$AA49*9554 -> 662.80875 | AC49: =AC$44/$AA49*9554 -> 597.125 | AD49: =AD$44/$AA49*9554 -> 537.4125 | AE49: =AE$44/$AA49*9554 -> 477.7 | AF49: =AF$44/$AA49*9554 -> 417.9875 | AG49: =AG$44/$AA49*9554 -> 358.275 | AH49: =AH$44/$AA49*9554 -> 298.5625 | AI49: =AI$44/$AA49*9554 -> 238.85 | ... AM49: =AM$44/$AA49*9554 -> 29.85625 | AR49: 125 | AS49: 99 | AT49: 71 | AU49: 45 | AV49: =AS49+5 -> 104
N50: 1800 | Q50: 150 | R50: 150 | S50: 124 | T50: 97 | U50: 70 | V50: 44 | W50: =T50+5 -> 102 | AA50: 1800 | AB50: =AB$44/$AA50*9554 -> 589.16333 | AC50: =AC$44/$AA50*9554 -> 530.77778 | AD50: =AD$44/$AA50*9554 -> 477.7 | AE50: =AE$44/$AA50*9554 -> 424.62222 | AF50: =AF$44/$AA50*9554 -> 371.54444 | AG50: =AG$44/$AA50*9554 -> 318.46667 | AH50: =AH$44/$AA50*9554 -> 265.38889 | AI50: =AI$44/$AA50*9554 -> 212.31111 | ... AM50: =AM$44/$AA50*9554 -> 26.538889 | AP50: 162 | AQ50: 162 | AR50: 120 | AS50: 97 | AT50: 70 | AU50: 44 | AV50: =AS50+5 -> 102
N51: 2000 | Q51: 140 | R51: 170 | S51: 121 | T51: 95 | U51: 69 | V51: 43 | W51: =T51+5 -> 100 | AA51: 2000 | AB51: =AB$44/$AA51*9554 -> 530.247 | AC51: =AC$44/$AA51*9554 -> 477.7 | AD51: =AD$44/$AA51*9554 -> 429.93 | AE51: =AE$44/$AA51*9554 -> 382.16 | AF51: =AF$44/$AA51*9554 -> 334.39 | AG51: =AG$44/$AA51*9554 -> 286.62 | AH51: =AH$44/$AA51*9554 -> 238.85 | AI51: =AI$44/$AA51*9554 -> 191.08 | ... AM51: =AM$44/$AA51*9554 -> 23.885 | AP51: 148 | AQ51: 178 | AR51: 117 | AS51: 95 | AT51: 69 | AU51: 43 | AV51: =AS51+5 -> 100
N52: 2200 | O52: 170 | P52: 170 | Q52: 134 | R52: 182 | S52: 119 | T52: 93 | U52: 68 | V52: 42 | W52: =T52+5 -> 98 | AA52: 2200 | AB52: =AB$44/$AA52*9554 -> 482.04273 | AC52: =AC$44/$AA52*9554 -> 434.27273 | AD52: =AD$44/$AA52*9554 -> 390.84545 | AE52: =AE$44/$AA52*9554 -> 347.41818 | AF52: =AF$44/$AA52*9554 -> 303.99091 | AG52: =AG$44/$AA52*9554 -> 260.56364 | AH52: =AH$44/$AA52*9554 -> 217.13636 | AI52: =AI$44/$AA52*9554 -> 173.70909 | ... AM52: =AM$44/$AA52*9554 -> 21.713636 | AN52: 170 | AO52: 170 | AP52: 142 | AQ52: 182 | AR52: 115 | AS52: 93 | AT52: 68 | AU52: 42 | AV52: =AS52+5 -> 98
N53: 2400 | O53: 165 | P53: 175 | Q53: 133 | R53: 187 | S53: 118 | T53: 91 | U53: 67 | V53: 41 | W53: =T53+5 -> 96 | AA53: 2400 | AB53: =AB$44/$AA53*9554 -> 441.8725 | AC53: =AC$44/$AA53*9554 -> 398.08333 | AD53: =AD$44/$AA53*9554 -> 358.275 | AE53: =AE$44/$AA53*9554 -> 318.46667 | AF53: =AF$44/$AA53*9554 -> 278.65833 | AG53: =AG$44/$AA53*9554 -> 238.85 | AH53: =AH$44/$AA53*9554 -> 199.04167 | AI53: =AI$44/$AA53*9554 -> 159.23333 | ... AM53: =AM$44/$AA53*9554 -> 19.904167 | AN53: 165 | AO53: 175 | AP53: 140 | AQ53: 187 | AR53: 115 | AS53: 91 | AT53: 67 | AU53: 41 | AV53: =AS53+5 -> 96
N54: 2600 | O54: 170 | P54: 170 | Q54: 135 | R54: 190 | S54: 118 | T54: 90 | U54: 66 | V54: 41 | W54: =T54+5 -> 95 | AA54: 2600 | AB54: =AB$44/$AA54*9554 -> 407.88231 | AC54: =AC$44/$AA54*9554 -> 367.46154 | AD54: =AD$44/$AA54*9554 -> 330.71538 | AE54: =AE$44/$AA54*9554 -> 293.96923 | AF54: =AF$44/$AA54*9554 -> 257.22308 | AG54: =AG$44/$AA54*9554 -> 220.47692 | AH54: =AH$44/$AA54*9554 -> 183.73077 | AI54: =AI$44/$AA54*9554 -> 146.98462 | ... AM54: =AM$44/$AA54*9554 -> 18.373077 | AN54: 170 | AO54: 170 | AP54: 138 | AQ54: 190 | AR54: 115 | AS54: 90 | AT54: 66 | AU54: 41 | AV54: =AS54+5 -> 95
N55: 2800 | Q55: 140 | R55: 188 | S55: 118 | T55: 90 | U55: 65 | V55: 40 | W55: =T55+5 -> 95 | AA55: 2800 | AB55: =AB$44/$AA55*9554 -> 378.74786 | AC55: =AC$44/$AA55*9554 -> 341.21429 | AD55: =AD$44/$AA55*9554 -> 307.09286 | AE55: =AE$44/$AA55*9554 -> 272.97143 | AF55: =AF$44/$AA55*9554 -> 238.85 | AG55: =AG$44/$AA55*9554 -> 204.72857 | AH55: =AH$44/$AA55*9554 -> 170.60714 | AI55: =AI$44/$AA55*9554 -> 136.48571 | ... AM55: =AM$44/$AA55*9554 -> 17.060714 | AP55: 140 | AQ55: 188 | AR55: 117 | AS55: 90 | AT55: 65 | AU55: 40 | AV55: =AS55+5 -> 95
N56: 3000 | Q56: 145 | R56: 180 | S56: 119 | T56: 91 | U56: 65 | V56: 40 | W56: =T56+5 -> 96 | AA56: 3000 | AB56: =AB$44/$AA56*9554 -> 353.498 | AC56: =AC$44/$AA56*9554 -> 318.46667 | AD56: =AD$44/$AA56*9554 -> 286.62 | AE56: =AE$44/$AA56*9554 -> 254.77333 | AF56: =AF$44/$AA56*9554 -> 222.92667 | AG56: =AG$44/$AA56*9554 -> 191.08 | AH56: =AH$44/$AA56*9554 -> 159.23333 | AI56: =AI$44/$AA56*9554 -> 127.38667 | ... AM56: =AM$44/$AA56*9554 -> 15.923333 | AP56: 145 | AQ56: 180 | AR56: 119 | AS56: 91 | AT56: 65 | AU56: 40 | AV56: =AS56+5 -> 96
N57: 3200 | Q57: 160 | R57: 160 | S57: 121 | T57: 92 | U57: 66 | V57: 41 | W57: =T57+5 -> 97 | AA57: 3200 | AB57: =AB$44/$AA57*9554 -> 331.40438 | AC57: =AC$44/$AA57*9554 -> 298.5625 | AD57: =AD$44/$AA57*9554 -> 268.70625 | AE57: =AE$44/$AA57*9554 -> 238.85 | AF57: =AF$44/$AA57*9554 -> 208.99375 | AG57: =AG$44/$AA57*9554 -> 179.1375 | AH57: =AH$44/$AA57*9554 -> 149.28125 | AI57: =AI$44/$AA57*9554 -> 119.425 | ... AM57: =AM$44/$AA57*9554 -> 14.928125 | AP57: 160 | AQ57: 160 | AR57: 121 | AS57: 92 | AT57: 66 | AU57: 41 | AV57: =AS57+5 -> 97
N58: 3400 | S58: 124 | T58: 93 | U58: 66 | V58: 41 | W58: =T58+5 -> 98 | AA58: 3400 | AB58: =AB$44/$AA58*9554 -> 311.91 | AC58: =AC$44/$AA58*9554 -> 281 | AD58: =AD$44/$AA58*9554 -> 252.9 | AE58: =AE$44/$AA58*9554 -> 224.8 | AF58: =AF$44/$AA58*9554 -> 196.7 | AG58: =AG$44/$AA58*9554 -> 168.6 | AH58: =AH$44/$AA58*9554 -> 140.5 | AI58: =AI$44/$AA58*9554 -> 112.4 | ... AM58: =AM$44/$AA58*9554 -> 14.05 | AR58: 124 | AS58: 93 | AT58: 66 | AU58: 41 | AV58: =AS58+5 -> 98
N59: 3600 | S59: 127 | T59: 94 | U59: 67 | V59: 41 | W59: =T59+5 -> 99 | AA59: 3600 | AB59: =AB$44/$AA59*9554 -> 294.58167 | AC59: =AC$44/$AA59*9554 -> 265.38889 | AD59: =AD$44/$AA59*9554 -> 238.85 | AE59: =AE$44/$AA59*9554 -> 212.31111 | AF59: =AF$44/$AA59*9554 -> 185.77222 | AG59: =AG$44/$AA59*9554 -> 159.23333 | AH59: =AH$44/$AA59*9554 -> 132.69444 | AI59: =AI$44/$AA59*9554 -> 106.15556 | ... AM59: =AM$44/$AA59*9554 -> 13.269444 | AR59: 127 | AS59: 94 | AT59: 67 | AU59: 41 | AV59: =AS59+5 -> 99
...

Sheet Aufgabe 1
A1: Aufgabe 1
B3: Kreuzen Sie bitte an, ob die Aussage richtig oder falsch ist.
F5: richtig falsch
A6: a) | B6: Bei einem Fahrzeug mit Transaxle Antriebsstrang sind der Motor und das Getriebe besonder kompakt miteinander verbaut. | G6: 0.5
A8: b) | B8: Das Modell von Ackermann gilt besonders für Kreisfahrten mit hoher Querbeschleunigung. | G8: 0.5
A10: c) | B10: Bei geringen Reifenschlupf λ handelt es sich größtenteils um Formänderungsschlupf. | G10: 0.5
A12: d) | B12: Beim seriellen Hybrid dient der Verbrennungsmotor nur zur Erzeugung der Energie für den antreibenden Elektromotor. | G12: 0.5
A14: e) | B14: Eine selbsttragende Karroserie benötigt einen Hilfsrahmen zur Aufnahme von Motor, Getriebe und der Achsen. | G14: 0.5
A16: f) | B16: Bei einem untersteuerndem Fahrzeug muss der Fahrer den Lenkwinkel erhöhen, um auf seinem Kurvenradius zu bleiben. | G16: 0.5
A18: g) | B18: Je weiter vorne der Fahrzeugschwerpunkt liegt, desto mehr tendiert das Fahrzeug zum übersteuern. | G18: 0.5
A20: h) | B20: Wirkt eine Kraft entlang eines Weges so verrichtet sie Arbeit. | G20: 0.5
F23: Summe 1 | G23: =SUM(G6:G21) -> 4

Sheet  2 Fahrwiderst
A1: Aufgabe 2
A3: Sie fahren mit Ihrem Fahrzeug mit einer Geschwindigkeit von vF=130km/h bei 3% Steigung und einem Radschlupf von 5%. Auf dem Fahrzeugdatenblatt sind Ihnen die notwendigen Fahrzeugdaten gegeben. a) Bestimmen Sie die Fahrwiderstandskräfte und den Zugkraftbedarf FZ. b) Bestimmen Sie die theoretische Fahrzeuggeschwindigkeit vtheoretisch (vth). c) Bestimmen sie die für diesen Betriebspunkt notwendige Radnabenleistung PN, die effektive Motorleistung Pe, die Verlustleistung im Triebstrang PVT und die Schlupfleistung PS.
J4: % | K4: Grad | L4: rad | M4: cos | N4: sin | O4: tan
J5: 1 | K5: =180/PI()*ATAN(J5/100) -> 0.5729387 | L5: =K5/180*PI() -> 0.0099996667 | M5: =COS(K5*PI()/180) -> 0.99995 | N5: =SIN(K5*PI()/180) -> 0.0099995 | O5: =TAN(K5*PI()/180) -> 0.01
J6: 2 | K6: =180/PI()*ATAN(J6/100) -> 1.1457628 | L6: =K6/180*PI() -> 0.019997334 | M6: =COS(K6*PI()/180) -> 0.99980006 | N6: =SIN(K6*PI()/180) -> 0.019996001 | O6: =TAN(K6*PI()/180) -> 0.02
J7: 3 | K7: =180/PI()*ATAN(J7/100) -> 1.718358 | L7: =K7/180*PI() -> 0.029991005 | M7: =COS(K7*PI()/180) -> 0.9995503 | N7: =SIN(K7*PI()/180) -> 0.029986509 | O7: =TAN(K7*PI()/180) -> 0.03
J8: 4 | K8: =180/PI()*ATAN(J8/100) -> 2.29061 | L8: =K8/180*PI() -> 0.039978687 | M8: =COS(K8*PI()/180) -> 0.99920096 | N8: =SIN(K8*PI()/180) -> 0.039968038 | O8: =TAN(K8*PI()/180) -> 0.04
J9: 5 | K9: =180/PI()*ATAN(J9/100) -> 2.8624052 | L9: =K9/180*PI() -> 0.049958396 | M9: =COS(K9*PI()/180) -> 0.99875234 | N9: =SIN(K9*PI()/180) -> 0.049937617 | O9: =TAN(K9*PI()/180) -> 0.05
J10: 6 | K10: =180/PI()*ATAN(J10/100) -> 3.4336304 | L10: =K10/180*PI() -> 0.059928155 | M10: =COS(K10*PI()/180) -> 0.99820485 | N10: =SIN(K10*PI()/180) -> 0.059892291 | O10: =TAN(K10*PI()/180) -> 0.06
J11: 7 | K11: =180/PI()*ATAN(J11/100) -> 4.0041729 | L11: =K11/180*PI() -> 0.069886002 | M11: =COS(K11*PI()/180) -> 0.99755897 | N11: =SIN(K11*PI()/180) -> 0.069829128 | O11: =TAN(K11*PI()/180) -> 0.07
A12: Aufgabe a) | C12: gegeben: | D12: v= | E12: 130 | F12: =E12/3.6 -> 36.111111 | J12: 8 | K12: =180/PI()*ATAN(J12/100) -> 4.5739213 | L12: =K12/180*PI() -> 0.079829986 | M12: =COS(K12*PI()/180) -> 0.99681528 | N12: =SIN(K12*PI()/180) -> 0.079745222 | O12: =TAN(K12*PI()/180) -> 0.08
D13: p= | E13: 0.03 | J13: 9 | K13: =180/PI()*ATAN(J13/100) -> 5.1427646 | L13: =K13/180*PI() -> 0.089758174 | M13: =COS(K13*PI()/180) -> 0.99597444 | N13: =SIN(K13*PI()/180) -> 0.089637699 | O13: =TAN(K13*PI()/180) -> 0.09
J14: 10 | K14: =180/PI()*ATAN(J14/100) -> 5.7105931 | L14: =K14/180*PI() -> 0.099668652 | M14: =COS(K14*PI()/180) -> 0.99503719 | N14: =SIN(K14*PI()/180) -> 0.099503719 | O14: =TAN(K14*PI()/180) -> 0.1 | R14: V_F | S14: v_th
G15: 1 | J15: 11 | K15: =180/PI()*ATAN(J15/100) -> 6.2772985 | L15: =K15/180*PI() -> 0.10955953 | M15: =COS(K15*PI()/180) -> 0.99400436 | N15: =SIN(K15*PI()/180) -> 0.10934048 | O15: =TAN(K15*PI()/180) -> 0.11 | R15: =V_F -> 130 | S15: =v_th -> 136.84211
B16: FLW= | C16: =CONCATENATE(0.5,"*",roh_Luft,"*",cw,"*",A,"*(",E12,"/",3.6,")^2") -> 0,5*1,18*0,3*2,4*(130/3,6)^2 | J16: 12 | K16: =180/PI()*ATAN(J16/100) -> 6.8427734 | L16: =K16/180*PI() -> 0.11942893 | M16: =COS(K16*PI()/180) -> 0.99287684 | N16: =SIN(K16*PI()/180) -> 0.11914522 | O16: =TAN(K16*PI()/180) -> 0.12 | P16: FB= | Q16: =S16/S15*3.6*1000 -> #REF! | R16: =R24-R23-R22-R19-R18-R17 -> #REF! | S16: =S24-S23-S22-S19-S18-S17 -> #REF! | U16: =Q16-Q31 -> #REF!
C17: FLW= | D17: =0.5*roh_Luft*cw*A*E12^2/3.6^2 -> 553.94444 | G17: 1 | J17: 13 | K17: =180/PI()*ATAN(J17/100) -> 7.4069121 | L17: =K17/180*PI() -> 0.129275 | M17: =COS(K17*PI()/180) -> 0.99165562 | N17: =SIN(K17*PI()/180) -> 0.12891523 | O17: =TAN(K17*PI()/180) -> 0.13 | P17: FLW= | Q17: =0.5*roh_Luft*cw*A*E12^2/3.6^2 -> 553.94444 | R17: =Q17*$R$15/3.6/1000 -> 20.003549 | S17: =Q17*$S$15/3.6/1000 -> 21.056368
J18: 14 | K18: =180/PI()*ATAN(J18/100) -> 7.9696104 | L18: =K18/180*PI() -> 0.13909594 | M18: =COS(K18*PI()/180) -> 0.99034175 | N18: =SIN(K18*PI()/180) -> 0.13864784 | O18: =TAN(K18*PI()/180) -> 0.14 | P18: FR= | Q18: =m_F_normal*g_Erdbeschl.*fr -> 127.53 | R18: =Q18*$R$15/3.6/1000 -> 4.60525 | S18: =Q18*$S$15/3.6/1000 -> 4.8476316
G19: 1 | J19: 15 | K19: =180/PI()*ATAN(J19/100) -> 8.5307656 | L19: =K19/180*PI() -> 0.14888995 | M19: =COS(K19*PI()/180) -> 0.98893635 | N19: =SIN(K19*PI()/180) -> 0.14834045 | O19: =TAN(K19*PI()/180) -> 0.15 | P19: FSt= | Q19: =m_F_normal*g_Erdbeschl.*p -> 382.59 | R19: =Q19*$R$15/3.6/1000 -> 13.81575 | S19: =Q19*$S$15/3.6/1000 -> 14.542895
B20: FR= | C20: =CONCATENATE(m_F_normal,"*",g_Erdbeschl.,"*",fr,"") -> 1300*9,81*0,01 | J20: 16 | K20: =180/PI()*ATAN(J20/100) -> 9.0902769 | L20: =K20/180*PI() -> 0.15865526 | M20: =COS(K20*PI()/180) -> 0.98744063 | N20: =SIN(K20*PI()/180) -> 0.1579905 | O20: =TAN(K20*PI()/180) -> 0.16 | P20: FZ= | Q20: =SUM(Q16:Q19) -> #REF! | U20: =Q20-Q35 -> #REF!
C21: FR= | D21: =m_F_normal*g_Erdbeschl.*fr -> 127.53 | G21: 1 | J21: 17 | K21: =180/PI()*ATAN(J21/100) -> 9.6480453 | L21: =K21/180*PI() -> 0.16839016 | M21: =COS(K21*PI()/180) -> 0.98585585 | N21: =SIN(K21*PI()/180) -> 0.16759549 | O21: =TAN(K21*PI()/180) -> 0.17
J22: 18 | K22: =180/PI()*ATAN(J22/100) -> 10.203974 | L22: =K22/180*PI() -> 0.17809294 | M22: =COS(K22*PI()/180) -> 0.98418332 | N22: =SIN(K22*PI()/180) -> 0.177153 | O22: =TAN(K22*PI()/180) -> 0.18 | P22: FVT= | Q22: =D60/V_F*3.6*1000 -> 71.493692 | R22: =Q22*$R$15/3.6/1000 -> 2.5817166 | S22: =R22 -> 2.5817166 | U22: =Q22-Q37 -> 0
G23: 1 | J23: 19 | K23: =180/PI()*ATAN(J23/100) -> 10.757967 | L23: =K23/180*PI() -> 0.18776195 | M23: =COS(K23*PI()/180) -> 0.98242445 | N23: =SIN(K23*PI()/180) -> 0.18666065 | O23: =TAN(K23*PI()/180) -> 0.19 | P23: FS= | Q23: =Q20*(v_th-V_F)/V_F -> #REF! | R23: =Q23*$R$15/3.6/1000 -> #REF! | U23: =Q23-Q38 -> #REF!
B24: FSt= | C24: =CONCATENATE(m_F_normal,"*",g_Erdbeschl.,"*",p) -> 1300*9,81*0,03 | J24: 20 | K24: =180/PI()*ATAN(J24/100) -> 11.309932 | L24: =K24/180*PI() -> 0.19739556 | M24: =COS(K24*PI()/180) -> 0.98058068 | N24: =SIN(K24*PI()/180) -> 0.19611614 | O24: =TAN(K24*PI()/180) -> 0.2 | R24: ='4 Fahrleistung'!#REF! -> #REF! | S24: ='4 Fahrleistung'!#REF! -> #REF!
C25: FSt= | D25: =m_F_normal*g_Erdbeschl.*p -> 382.59 | G25: 1 | J25: 21 | K25: =180/PI()*ATAN(J25/100) -> 11.859779 | L25: =K25/180*PI() -> 0.20699219 | M25: =COS(K25*PI()/180) -> 0.9786535 | N25: =SIN(K25*PI()/180) -> 0.20551723 | O25: =TAN(K25*PI()/180) -> 0.21 | R25: =Q20+Q22+Q23 -> #REF! | S25: =Q20+Q22 -> #REF! | U25: =R25-R40 -> #REF! | V25: =S25-S40 -> #REF!
C26: FVT= | D26: =D60/V_F*3.6*1000 -> 71.493692 | J26: 22 | K26: =180/PI()*ATAN(J26/100) -> 12.407419 | L26: =K26/180*PI() -> 0.2165503 | M26: =COS(K26*PI()/180) -> 0.97664447 | N26: =SIN(K26*PI()/180) -> 0.21486178 | O26: =TAN(K26*PI()/180) -> 0.22
C27: FS= | D27: =D56/V_F*3.6*1000 -> 56.003392 | J27: 23 | K27: =180/PI()*ATAN(J27/100) -> 12.952765 | L27: =K27/180*PI() -> 0.22606839 | M27: =COS(K27*PI()/180) -> 0.97455519 | N27: =SIN(K27*PI()/180) -> 0.22414769 | O27: =TAN(K27*PI()/180) -> 0.23
C28: Fe= | D28: =D27+D25+D26+D21+D17 -> 1191.5615 | E28: =D52/V_F*3.6*1000 -> 1191.5615 | J28: 24 | K28: =180/PI()*ATAN(J28/100) -> 13.495733 | L28: =K28/180*PI() -> 0.23554498 | M28: =COS(K28*PI()/180) -> 0.9723873 | N28: =SIN(K28*PI()/180) -> 0.23337295 | O28: =TAN(K28*PI()/180) -> 0.24
J29: 25 | K29: =180/PI()*ATAN(J29/100) -> 14.036243 | L29: =K29/180*PI() -> 0.24497866 | M29: =COS(K29*PI()/180) -> 0.9701425 | N29: =SIN(K29*PI()/180) -> 0.24253563 | O29: =TAN(K29*PI()/180) -> 0.25 | R29: V_F | S29: v_th
G30: 1 | J30: 26 | K30: =180/PI()*ATAN(J30/100) -> 14.574216 | L30: =K30/180*PI() -> 0.25436806 | M30: =COS(K30*PI()/180) -> 0.96782251 | N30: =SIN(K30*PI()/180) -> 0.25163385 | O30: =TAN(K30*PI()/180) -> 0.26 | R30: =V_F -> 130 | S30: =v_th -> 136.84211
B31: FZ= | C31: =CONCATENATE(ROUND(D17,2),"+",D21,"+",D25) -> 553,94+127,53+382,59 | J31: 27 | K31: =180/PI()*ATAN(J31/100) -> 15.109575 | L31: =K31/180*PI() -> 0.26371183 | M31: =COS(K31*PI()/180) -> 0.96542908 | N31: =SIN(K31*PI()/180) -> 0.26066585 | O31: =TAN(K31*PI()/180) -> 0.27 | P31: FB= | Q31: =S31/S30*3.6*1000 -> 0 | R31: =R39-R38-R37-R34-R33-R32 -> 0 | S31: =S39-S38-S37-S34-S33-S32 -> 0
C32: FZ= | D32: =D17+D21+D25 -> 1064.0644 | G32: 1 | J32: 28 | K32: =180/PI()*ATAN(J32/100) -> 15.642246 | L32: =K32/180*PI() -> 0.2730087 | M32: =COS(K32*PI()/180) -> 0.96296402 | N32: =SIN(K32*PI()/180) -> 0.26962993 | O32: =TAN(K32*PI()/180) -> 0.28 | P32: FLW= | Q32: =0.5*roh_Luft*cw*A*E12^2/3.6^2 -> 553.94444 | R32: =Q17*$R$15/3.6/1000 -> 20.003549 | S32: =Q17*$S$15/3.6/1000 -> 21.056368
H33: =SUM(G15:G32) -> 8 | J33: 29 | K33: =180/PI()*ATAN(J33/100) -> 16.172159 | L33: =K33/180*PI() -> 0.28225742 | M33: =COS(K33*PI()/180) -> 0.96042914 | N33: =SIN(K33*PI()/180) -> 0.27852445 | O33: =TAN(K33*PI()/180) -> 0.29 | P33: FR= | Q33: =m_F_normal*g_Erdbeschl.*fr -> 127.53 | R33: =Q33*$R$15/3.6/1000 -> 4.60525 | S33: =Q33*$S$15/3.6/1000 -> 4.8476316
D34: λA = | E34: 0.05 | J34: 30 | K34: =180/PI()*ATAN(J34/100) -> 16.699244 | L34: =K34/180*PI() -> 0.29145679 | M34: =COS(K34*PI()/180) -> 0.95782629 | N34: =SIN(K34*PI()/180) -> 0.28734789 | O34: =TAN(K34*PI()/180) -> 0.3 | P34: FSt= | Q34: =m_F_normal*g_Erdbeschl.*p -> 382.59 | R34: =Q34*$R$15/3.6/1000 -> 13.81575 | S34: =Q34*$S$15/3.6/1000 -> 14.542895
A35: Aufgabe b) | J35: 31 | K35: =180/PI()*ATAN(J35/100) -> 17.223436 | L35: =K35/180*PI() -> 0.30060567 | M35: =COS(K35*PI()/180) -> 0.95515733 | N35: =SIN(K35*PI()/180) -> 0.29609877 | O35: =TAN(K35*PI()/180) -> 0.31 | P35: FZ= | Q35: =SUM(Q31:Q34) -> 1064.0644
G36: 1 | J36: 32 | K36: =180/PI()*ATAN(J36/100) -> 17.744672 | L36: =K36/180*PI() -> 0.30970294 | M36: =COS(K36*PI()/180) -> 0.95242415 | N36: =SIN(K36*PI()/180) -> 0.30477573 | O36: =TAN(K36*PI()/180) -> 0.32
J37: 33 | K37: =180/PI()*ATAN(J37/100) -> 18.26289 | L37: =K37/180*PI() -> 0.31874756 | M37: =COS(K37*PI()/180) -> 0.94962865 | N37: =SIN(K37*PI()/180) -> 0.31337745 | O37: =TAN(K37*PI()/180) -> 0.33 | P37: FVT= | Q37: =R39*(1-eta_Tr)/V_F*3.6*1000 -> 71.493692 | R37: =Q37*$R$30/3.6/1000 -> 2.5817166 | S37: =R37 -> 2.5817166
G38: 2 | J38: 34 | K38: =180/PI()*ATAN(J38/100) -> 18.778033 | L38: =K38/180*PI() -> 0.32773851 | M38: =COS(K38*PI()/180) -> 0.94677274 | N38: =SIN(K38*PI()/180) -> 0.32190273 | O38: =TAN(K38*PI()/180) -> 0.34 | P38: FS= | Q38: =Q35*(v_th-V_F)/V_F -> 56.003392 | R38: =D56 -> 2.0223447
J39: 35 | K39: =180/PI()*ATAN(J39/100) -> 19.290046 | L39: =K39/180*PI() -> 0.33667482 | M39: =COS(K39*PI()/180) -> 0.94385836 | N39: =SIN(K39*PI()/180) -> 0.33035042 | O39: =TAN(K39*PI()/180) -> 0.35 | R39: =D52 -> 43.028611 | S39: =D52 -> 43.028611
J40: 36 | K40: =180/PI()*ATAN(J40/100) -> 19.798876 | L40: =K40/180*PI() -> 0.34555558 | M40: =COS(K40*PI()/180) -> 0.94088741 | N40: =SIN(K40*PI()/180) -> 0.33871947 | O40: =TAN(K40*PI()/180) -> 0.36 | R40: =Q35+Q37+Q38 -> 1191.5615 | S40: =Q35+Q37 -> 1135.5581
B41: vth = | C41: =CONCATENATE(E12," / ","1-",LambdaA) -> 130 / 1-0,05 | J41: 37 | K41: =180/PI()*ATAN(J41/100) -> 20.304474 | L41: =K41/180*PI() -> 0.35437992 | M41: =COS(K41*PI()/180) -> 0.93786184 | N41: =SIN(K41*PI()/180) -> 0.34700888 | O41: =TAN(K41*PI()/180) -> 0.37
...

Sheet 3 Kraftstoff
A1: Aufgabe 3
A3: Benutzen Sie für die folgenden Berechnungen, soweit Ihnen möglich, die ermittelten Werte aus Aufgabe 3. Ersatzwerte: (Pe = 50kW, vth=145km/h, vF=137,8km/h) a) Zeichnen Sie in das Muscheldiagramm die Linie konstanter Leistung für die benötigte effektiven Motorleistung in das Muscheldiagramm ein. Nutzen Sie hierfür die in der Tabelle gegebenen Stützstellen. b) Bestimmen Sie die Motordrehzahl für den gegebenen Betriebspunkt unter der Annahme, dass Sie im 5. Gang fahren und zeichnen diesen in das Diagramm ein (Markierung mit „A“). c) Bestimmen Sie den Kraftstoffverbrauch in dem gegebenen Betriebspunkt.
A12: Aufbabe a) | E12: Ersatz_PE= | F12: 50 | G12: 1
B13: MMotor= | C13: =CONCATENATE(ROUND(' 2 Fahrwiderst'!D52,2)," * 9549 / ",ROUND(B18,2)) -> 43,03 * 9549 / 2250 | E13: Ersatz vth= | F13: 145
C14: MMotor= | D14: =' 2 Fahrwiderst'!D52*9549/B18 -> 182.61342 | E14: Ersatz vF= | F14: =F13*0.95 -> 137.75 | G14: 1
C15: MMotor= | D15: =F12*9549/B18 -> 212.2
C16: Ersatzwert
B17: nMot | C17: =F12 -> 50 | D17: =' 2 Fahrwiderst'!D52 -> 43.028611
B18: 2250 | C18: =C$17/$B18*9554 -> 212.31111 | D18: =D$17/$B18*9549 -> 182.61342 | G18: 0.5
B19: 3000 | C19: =C$17/$B19*9554 -> 159.23333 | D19: =D$17/$B19*9549 -> 136.96007 | G19: 0.5
B20: 4500 | C20: =C$17/$B20*9554 -> 106.15556 | D20: =D$17/$B20*9549 -> 91.306712 | G20: 0.5
B21: 6000 | C21: =C$17/$B21*9554 -> 79.616667 | D21: =D$17/$B21*9549 -> 68.480034 | G21: 0.5
F23: Graphik: | G23: 2
H24: =SUM(G12:G23) -> 6
A25: Aufgabe 4b)
G27: 1
G29: 1
B31: nM= | C31: =CONCATENATE(ROUND(v_th,2)," * ",i_Achse," *",I_5," / ( 0,3768 *",rdyn,")") -> 136,84 * 3,46 *0,8 / ( 0,3768 *0,32)
C32: nM= | D32: =v_th*i_Achse*I_5/0.3768/rdyn -> 3141.4124 | G32: 1
C33: nM= | D33: =F13*i_Achse*I_5/0.3768/rdyn -> 3328.689
A34: Mmotor= | B34: =' 2 Fahrwiderst'!D52*9549/'3 Kraftstoff'!D32 -> 130.79473 | C34: nicht notwendig
A35: Ersatz_Mmotor= | B35: =F12*9549/'3 Kraftstoff'!D33 -> 143.43485 | C35: nicht notwendig | E35: Betriebspunkt im Diagramm | G35: 1
H36: =SUM(G26:G35) -> 4
A37: Aufgabe 4c)
D38: be= | E38: 263 | G38: 1
D39: be= | E39: 265
G40: 1
B41: BS= | C41: =CONCATENATE(ROUND(' 2 Fahrwiderst'!D52,2)," * ",'3 Kraftstoff'!E38," / ( ",roh_Kraftst.," * ",' 2 Fahrwiderst'!E12," )") -> 43,03 * 263 / ( 0,8 * 130 )
C42: BS= | D42: =' 2 Fahrwiderst'!D52 *E38/(roh_Kraftst.*' 2 Fahrwiderst'!E12)/10 -> 10.881274 | G42: 1
C43: BS= | D43: =F12 *E39/(roh_Kraftst.*F14)/10 -> 12.023593
H44: =SUM(G38:G43) -> 3
F45: Summe: | G45: =SUM(G12:G44) -> 13

Sheet 4 Fahrleistung
A1: Aufgabe 4
A3: Sie fahren mit Ihrem Fahrzeug mit v=100km/h im 3. Gang ohne Schlupf in der Ebene. (siehe „Betriebspunkt 100“ im Diagramm). a) Wie groß ist die Überschussleistung in diesem Betriebspunkt? (Sie dürfen hier gerne Werte aus dem Diagramm herauslesen). b) Bestimmen Sie den Drehmassenzuschlagsfaktor e3. c) Bestimmen Sie die maximale Beschleunigung, die unter Vollast mit den Fahrzeugwerten im Datenblatt möglich ist. Berücksichtigen Sie auch die rotierenden Massen.
A12: Aufgabe a) | E12: v= | F12: 100
A13: Pe = | B13: =Nebenrechnung_5!D52 -> 13.454722 | E13: Aus Diagramm herausgelesen. Mü = | F13: 170 | G13: 2
A14: M= | B14: =B13/B15*9549 -> 30.214648
A15: n = | B15: =F12*i_Achse*I_3/0.3768/rdyn -> 4252.2135 | G15: 1
E17: Pü= | F17: =F13*B15/9549 -> 75.70178 | G17: 1
G20: 1
B22: Jred= | C22: =CONCATENATE(" 4 * ",J_Rad," + ",i_Achse," ^2 * ",J_Triebstrang," + ",i_Achse,"^2 * ",ROUND(I_5,2),"^2 * (",J_Kuppl," + ",J_Getr," + ",J_Motor," )") -> 4 * 2,5 + 3,46 ^2 * 0,1 + 3,46^2 * 0,8^2 * (0,1 + 0,15 + 0,3 ) | G22: 1
C23: Jred= | D23: =4 *J_Rad + i_Achse ^2 *J_Triebstrang + i_Achse^2 * I_3^2 *( J_Kuppl + J_Getr+J_Motor) -> 25.655371 | G23: 1
G26: 1
B28: ε= | C28: =J_red/m_F_normal/rdyn^2 -> 0.19272364 | G28: 1
G30: 1
B31: e3= | C31: =1+C28 -> 1.1927236 | G31: 1
G33: 1
D35: PB= | E35: =P_ü*eta_Tr -> 71.159673 | G35: 1
G37: 1
G39: 1
B41: a= | C41: =CONCATENATE(ROUND(P_B,2),"*1000 / ( ",ROUND(F12,2),"/3,6 * ",ROUND(e_5,2)," * ",m_F_normal," )") -> 71,16*1000 / ( 100/3,6 * 1,19 * 1300 )
C42: a= | D42: =(P_B )*1000/ ( F12/3.6 *e_3 *m_F_normal) -> 1.6521644 | G42: 1
F45: Summe: | G45: =SUM(G12:G42) -> 16

Sheet 5 Einspur
A1: Aufgabe 5
A3: Bei einem Wettbewerb sollen im Rahmen der dynamischen Disziplinen auch Kreisfahrten (in der Ebene) auf einer Kreisbahn durchgeführt werden. Im Vorfeld sollen Berechnungen durchgeführt werden, um das Potential des Fahrzeuges abzuschätzen. Auf dem Datenblatt sind Ihnen die notwendigen Fahrzeugdaten gegeben. a) Wie groß müsste der Radius gewählt werden, damit das Fahrzeug mit 130km/h nicht aus der Kurve hinausrutscht (Schleudergrenze)? b) Berechnen Sie den Lenkwinkel für den in Teil a) ermittelten Radius. Geben Sie das Ergebnis in grad an. (Ersatzwert: R = 150m) c) Wie müsste das Verhältnis von lv/lh gewählt werden, damit sich ein neutrales Fahrverhalten in diesem Betriebspunkt ergibt?
A14: Aufgabe 5a.)
A15: Schleudergrenze
G17: 1
G19: 1
B20: R= | C20: =CONCATENATE("( ",V_F," / 3,6 )^2 / ( ",g_Erdbeschl.," * ",Mue," )") -> ( 130 / 3,6 )^2 / ( 9,81 * 1,06 )
E21: Rgrenz_Schleuder= | F21: =(V_F/3.6)^2/(g_Erdbeschl.*Mue) -> 125.40268 | G21: 1
H22: =SUM(G15:G21) -> 3
E23: Ersatzwert= | F23: 150
A25: Aufgabe b)
G26: 1 | H26: =1300/3.6*(2/50000-1.6/60000) -> 0.0048148148
A28: EG= | B28: =CONCATENATE(m_F_normal," / ",l_0," * ( ",lh," / ",C_av," - ", l_0-lh," / ",C_ah," )") -> 1300 / 2,8 * ( 1,6 / 50000 - 1,2 / 60000 )
A29: EG= | B29: =m_F_normal/l_0*(lh/C_av-(l_0-lh)/C_ah) -> 0.0055714286 | G29: 1
G32: 1
E34: ay = | F34: =(V_F/3.6)^2/Radius -> 10.3986 | G34: 1
E35: ay = | F35: =(V_F/3.6)^2/F23 -> 8.6934156
G37: 1
B39: =l_0/Radius -> 0.022328071 | C39: + | D39: =B29*ay -> 0.057935057 | E39: δ = | F39: =B39+D39 -> 0.080263128 | G39: 1
B40: =B39*180/PI() -> 1.2793042 | C40: + | D40: =D39*180/PI() -> 3.3194343 | E40: δ = | F40: =F39*180/PI() -> 4.5987385 | G40: 1
B41: =l_0/F23 -> 0.018666667 | C41: + | D41: =B29*F35 -> 0.048434744 | E41: δ = | F41: =B41+D41 -> 0.067101411
B42: =B41*180/PI() -> 1.0695212 | C42: + | D42: =D41*180/PI() -> 2.7751064 | E42: δ = | F42: =F41*180/PI() -> 3.8446276 | H42: =SUM(G26:G41) -> 7
A44: Aufgabe c)
G47: 1
B49: --> | D49: --> | G49: 1
C51: --> | F51: =C_ah/C_av -> 1.2 | G51: 1
H52: =SUM(G47:G52) -> 3
F53: Summe: | G53: =SUM(G15:G52) -> 13

Sheet 6 Schwerpunkt 
A1: Aufgabe 6
A3: Das abgebildete Motorrad fährt mit einer konstanten Geschwindigkeit von 108 km/h. Lösen Sie diese Aufgabe mit Hilfe der Statik-Ansätze ∑F=0 und ∑M=0. a) Zeichnen Sie die für die Berechnung erforderlichen Kräfte, die Längen- und Höhenmaße in das linke Bild der Skizze ein. b) Berechnen sie die Beschleunigung die notwendig ist, damit das Vorderrad des Motorrads von der Straße abhebt. Das Motorrad hat folgende spezifischen Fahrzeugwerte:
A11: Gegeben: | B11: hLW= | C11: 0.9 | D11: cw= | E11: 0.6 | F11: v= | G11: 108
B12: hs= | C12: 0.5 | D12: A= | E12: 0.7
B13: l0= | C13: 1.6 | D13: ρLuft = | E13: 1.18
B14: lh= | C14: 0.8 | D14: m= | E14: 270 | F14: (inklusive Fahrer)
A27: Aufgabe a)
G28: 3 | H28: Längen | I28: 3 x 0,5 | J28: 1.5
G29: 1 | H29: Höhen | I29: 1 x 0,5 | J29: 0.5
G30: 4 | H30: Kräfte | I30: 4 x 0,5 | J30: 2
H31: 4
A36: Aufgabe c) | H36: 3
H39: 1
F41: FG = | G41: =(m_Motorrad)*g_Erdbeschl. -> 2648.7 | H41: 1
F42: FLW = | G42: =0.5*roh_Luft*cw_motorrad*A_Motorrad*(G11/3.6)^2 -> 223.02 | H42: 1
B43: FB= | C43: =CONCATENATE("(",ROUND(FG_Motorrad,1)," * ",l_h_Motorrad,"+",ROUND(F_lW_Motorrad,1),"*",h_LW_Motorrad,") / ", h_s_Motorrad) -> (2648,7 * 0,8+223*0,9) / 0,5 | F43: FB= | G43: =(FG_Motorrad*l_h_Motorrad-G42*h_LW_Motorrad)/h_s_Motorrad -> 3836.484 | H43: 1
H45: 1
F46: a= | G46: {=G43/m_Motorrad} -> 14.2092 | H46: 1
G49: Summe: | H49: =SUM(H30:H47) -> 13

Sheet Punkteverteilung
D7: Aufgabe 1 | E7: ='Aufgabe 1'!G23 -> 4
D8: Aufgabe 2 | E8: =' 2 Fahrwiderst'!G62 -> 20
D9: Aufgabe 3 | E9: ='3 Kraftstoff'!G45 -> 13
D10: Aufgabe 4 | E10: ='4 Fahrleistung'!G45 -> 16
D11: Aufgabe 5 | E11: ='5 Einspur'!G53 -> 13
D12: Aufgabe 6 | E12: ='6 Schwerpunkt '!H49 -> 13
E13: =SUM(E6:E12) -> 79

Sheet Nebenrechnung_5
A1: Aufgabe 3
A3: Sie fahren mit Ihrem Fahrzeug mit einer Geschwindigkeit von vF=130km/h bei 3% Steigung und einem Radschlupf von 5%. Auf dem Fahrzeugdatenblatt sind Ihnen die notwendigen Fahrzeugdaten gegeben. a) Bestimmen Sie die Fahrwiderstandskräfte und den Zugkraftbedarf FZ. b) Bestimmen Sie die theoretische Fahrzeuggeschwindigkeit vheoretisch (vth). c) Bestimmen sie die für diesen Betriebspunkt notwendige Radnabenleistung PN, die effektive Motorleistung PE, die Verlustleistung im Triebstrang PVT und die Schlupfleistung PS.
J4: % | K4: Grad | L4: rad | M4: cos | N4: sin | O4: tan
J5: 1 | K5: =180/PI()*ATAN(J5/100) -> 0.5729387 | L5: =K5/180*PI() -> 0.0099996667 | M5: =COS(K5*PI()/180) -> 0.99995 | N5: =SIN(K5*PI()/180) -> 0.0099995 | O5: =TAN(K5*PI()/180) -> 0.01
J6: 2 | K6: =180/PI()*ATAN(J6/100) -> 1.1457628 | L6: =K6/180*PI() -> 0.019997334 | M6: =COS(K6*PI()/180) -> 0.99980006 | N6: =SIN(K6*PI()/180) -> 0.019996001 | O6: =TAN(K6*PI()/180) -> 0.02
J7: 3 | K7: =180/PI()*ATAN(J7/100) -> 1.718358 | L7: =K7/180*PI() -> 0.029991005 | M7: =COS(K7*PI()/180) -> 0.9995503 | N7: =SIN(K7*PI()/180) -> 0.029986509 | O7: =TAN(K7*PI()/180) -> 0.03
J8: 4 | K8: =180/PI()*ATAN(J8/100) -> 2.29061 | L8: =K8/180*PI() -> 0.039978687 | M8: =COS(K8*PI()/180) -> 0.99920096 | N8: =SIN(K8*PI()/180) -> 0.039968038 | O8: =TAN(K8*PI()/180) -> 0.04
J9: 5 | K9: =180/PI()*ATAN(J9/100) -> 2.8624052 | L9: =K9/180*PI() -> 0.049958396 | M9: =COS(K9*PI()/180) -> 0.99875234 | N9: =SIN(K9*PI()/180) -> 0.049937617 | O9: =TAN(K9*PI()/180) -> 0.05
J10: 6 | K10: =180/PI()*ATAN(J10/100) -> 3.4336304 | L10: =K10/180*PI() -> 0.059928155 | M10: =COS(K10*PI()/180) -> 0.99820485 | N10: =SIN(K10*PI()/180) -> 0.059892291 | O10: =TAN(K10*PI()/180) -> 0.06
J11: 7 | K11: =180/PI()*ATAN(J11/100) -> 4.0041729 | L11: =K11/180*PI() -> 0.069886002 | M11: =COS(K11*PI()/180) -> 0.99755897 | N11: =SIN(K11*PI()/180) -> 0.069829128 | O11: =TAN(K11*PI()/180) -> 0.07
A12: Aufgabe a) | C12: gegeben: | D12: v= | E12: 100 | F12: =E12/3.6 -> 27.777778 | J12: 8 | K12: =180/PI()*ATAN(J12/100) -> 4.5739213 | L12: =K12/180*PI() -> 0.079829986 | M12: =COS(K12*PI()/180) -> 0.99681528 | N12: =SIN(K12*PI()/180) -> 0.079745222 | O12: =TAN(K12*PI()/180) -> 0.08
D13: p= | E13: 0 | J13: 9 | K13: =180/PI()*ATAN(J13/100) -> 5.1427646 | L13: =K13/180*PI() -> 0.089758174 | M13: =COS(K13*PI()/180) -> 0.99597444 | N13: =SIN(K13*PI()/180) -> 0.089637699 | O13: =TAN(K13*PI()/180) -> 0.09
J14: 10 | K14: =180/PI()*ATAN(J14/100) -> 5.7105931 | L14: =K14/180*PI() -> 0.099668652 | M14: =COS(K14*PI()/180) -> 0.99503719 | N14: =SIN(K14*PI()/180) -> 0.099503719 | O14: =TAN(K14*PI()/180) -> 0.1 | R14: V_F | S14: v_th
G15: 1 | J15: 11 | K15: =180/PI()*ATAN(J15/100) -> 6.2772985 | L15: =K15/180*PI() -> 0.10955953 | M15: =COS(K15*PI()/180) -> 0.99400436 | N15: =SIN(K15*PI()/180) -> 0.10934048 | O15: =TAN(K15*PI()/180) -> 0.11 | R15: =V_F -> 100 | S15: =v_th -> 100
B16: FLW= | C16: =CONCATENATE(0.5,"*",roh_Luft,"*",cw,"*",A,"*(",E12,"/",3.6,")^2") -> 0,5*1,18*0,3*2,4*(100/3,6)^2 | J16: 12 | K16: =180/PI()*ATAN(J16/100) -> 6.8427734 | L16: =K16/180*PI() -> 0.11942893 | M16: =COS(K16*PI()/180) -> 0.99287684 | N16: =SIN(K16*PI()/180) -> 0.11914522 | O16: =TAN(K16*PI()/180) -> 0.12 | P16: FB= | Q16: =S16/S15*3.6*1000 -> #REF! | R16: =R24-R23-R22-R19-R18-R17 -> #REF! | S16: =S24-S23-S22-S19-S18-S17 -> #REF! | U16: =Q16-Q31 -> #REF!
C17: FLW= | D17: =0.5*roh_Luft*cw*A*E12^2/3.6^2 -> 327.77778 | G17: 1 | J17: 13 | K17: =180/PI()*ATAN(J17/100) -> 7.4069121 | L17: =K17/180*PI() -> 0.129275 | M17: =COS(K17*PI()/180) -> 0.99165562 | N17: =SIN(K17*PI()/180) -> 0.12891523 | O17: =TAN(K17*PI()/180) -> 0.13 | P17: FLW= | Q17: =0.5*roh_Luft*cw*A*E12^2/3.6^2 -> 327.77778 | R17: =Q17*$R$15/3.6/1000 -> 9.1049383 | S17: =Q17*$S$15/3.6/1000 -> 9.1049383
J18: 14 | K18: =180/PI()*ATAN(J18/100) -> 7.9696104 | L18: =K18/180*PI() -> 0.13909594 | M18: =COS(K18*PI()/180) -> 0.99034175 | N18: =SIN(K18*PI()/180) -> 0.13864784 | O18: =TAN(K18*PI()/180) -> 0.14 | P18: FR= | Q18: =m_F_normal*g_Erdbeschl.*fr -> 127.53 | R18: =Q18*$R$15/3.6/1000 -> 3.5425 | S18: =Q18*$S$15/3.6/1000 -> 3.5425
G19: 1 | J19: 15 | K19: =180/PI()*ATAN(J19/100) -> 8.5307656 | L19: =K19/180*PI() -> 0.14888995 | M19: =COS(K19*PI()/180) -> 0.98893635 | N19: =SIN(K19*PI()/180) -> 0.14834045 | O19: =TAN(K19*PI()/180) -> 0.15 | P19: FSt= | Q19: =m_F_normal*g_Erdbeschl.*p -> 0 | R19: =Q19*$R$15/3.6/1000 -> 0 | S19: =Q19*$S$15/3.6/1000 -> 0
B20: FR= | C20: =CONCATENATE(m_F_normal,"*",g_Erdbeschl.,"*",fr,"") -> 1300*9,81*0,01 | J20: 16 | K20: =180/PI()*ATAN(J20/100) -> 9.0902769 | L20: =K20/180*PI() -> 0.15865526 | M20: =COS(K20*PI()/180) -> 0.98744063 | N20: =SIN(K20*PI()/180) -> 0.1579905 | O20: =TAN(K20*PI()/180) -> 0.16 | P20: FZ= | Q20: =SUM(Q16:Q19) -> #REF! | U20: =Q20-Q35 -> #REF!
C21: FR= | D21: =m_F_normal*g_Erdbeschl.*fr -> 127.53 | G21: 1 | J21: 17 | K21: =180/PI()*ATAN(J21/100) -> 9.6480453 | L21: =K21/180*PI() -> 0.16839016 | M21: =COS(K21*PI()/180) -> 0.98585585 | N21: =SIN(K21*PI()/180) -> 0.16759549 | O21: =TAN(K21*PI()/180) -> 0.17
J22: 18 | K22: =180/PI()*ATAN(J22/100) -> 10.203974 | L22: =K22/180*PI() -> 0.17809294 | M22: =COS(K22*PI()/180) -> 0.98418332 | N22: =SIN(K22*PI()/180) -> 0.177153 | O22: =TAN(K22*PI()/180) -> 0.18 | P22: FVT= | Q22: =D60/V_F*3.6*1000 -> 29.062199 | R22: =Q22*$R$15/3.6/1000 -> 0.80728329 | S22: =R22 -> 0.80728329 | U22: =Q22-Q37 -> 0
G23: 1 | J23: 19 | K23: =180/PI()*ATAN(J23/100) -> 10.757967 | L23: =K23/180*PI() -> 0.18776195 | M23: =COS(K23*PI()/180) -> 0.98242445 | N23: =SIN(K23*PI()/180) -> 0.18666065 | O23: =TAN(K23*PI()/180) -> 0.19 | P23: FS= | Q23: =Q20*(v_th-V_F)/V_F -> #REF! | R23: =Q23*$R$15/3.6/1000 -> #REF! | U23: =Q23-Q38 -> #REF!
B24: FSt= | C24: =CONCATENATE(m_F_normal,"*",g_Erdbeschl.,"*",p) -> 1300*9,81*0 | J24: 20 | K24: =180/PI()*ATAN(J24/100) -> 11.309932 | L24: =K24/180*PI() -> 0.19739556 | M24: =COS(K24*PI()/180) -> 0.98058068 | N24: =SIN(K24*PI()/180) -> 0.19611614 | O24: =TAN(K24*PI()/180) -> 0.2 | R24: ='4 Fahrleistung'!#REF! -> #REF! | S24: ='4 Fahrleistung'!#REF! -> #REF!
C25: FSt= | D25: =m_F_normal*g_Erdbeschl.*p -> 0 | G25: 1 | J25: 21 | K25: =180/PI()*ATAN(J25/100) -> 11.859779 | L25: =K25/180*PI() -> 0.20699219 | M25: =COS(K25*PI()/180) -> 0.9786535 | N25: =SIN(K25*PI()/180) -> 0.20551723 | O25: =TAN(K25*PI()/180) -> 0.21 | R25: =Q20+Q22+Q23 -> #REF! | S25: =Q20+Q22 -> #REF! | U25: =R25-R40 -> #REF! | V25: =S25-S40 -> #REF!
C26: FVT= | D26: =D60/V_F*3.6*1000 -> 29.062199 | J26: 22 | K26: =180/PI()*ATAN(J26/100) -> 12.407419 | L26: =K26/180*PI() -> 0.2165503 | M26: =COS(K26*PI()/180) -> 0.97664447 | N26: =SIN(K26*PI()/180) -> 0.21486178 | O26: =TAN(K26*PI()/180) -> 0.22
C27: FS= | D27: =D56/V_F*3.6*1000 -> 0 | J27: 23 | K27: =180/PI()*ATAN(J27/100) -> 12.952765 | L27: =K27/180*PI() -> 0.22606839 | M27: =COS(K27*PI()/180) -> 0.97455519 | N27: =SIN(K27*PI()/180) -> 0.22414769 | O27: =TAN(K27*PI()/180) -> 0.23
C28: Fe= | D28: =D27+D25+D26+D21+D17 -> 484.36998 | E28: =D52/V_F*3.6*1000 -> 484.36998 | J28: 24 | K28: =180/PI()*ATAN(J28/100) -> 13.495733 | L28: =K28/180*PI() -> 0.23554498 | M28: =COS(K28*PI()/180) -> 0.9723873 | N28: =SIN(K28*PI()/180) -> 0.23337295 | O28: =TAN(K28*PI()/180) -> 0.24
J29: 25 | K29: =180/PI()*ATAN(J29/100) -> 14.036243 | L29: =K29/180*PI() -> 0.24497866 | M29: =COS(K29*PI()/180) -> 0.9701425 | N29: =SIN(K29*PI()/180) -> 0.24253563 | O29: =TAN(K29*PI()/180) -> 0.25 | R29: V_F | S29: v_th
G30: 1 | J30: 26 | K30: =180/PI()*ATAN(J30/100) -> 14.574216 | L30: =K30/180*PI() -> 0.25436806 | M30: =COS(K30*PI()/180) -> 0.96782251 | N30: =SIN(K30*PI()/180) -> 0.25163385 | O30: =TAN(K30*PI()/180) -> 0.26 | R30: =V_F -> 100 | S30: =v_th -> 100
B31: FZ= | C31: =CONCATENATE(ROUND(D17,2),"+",D21,"+",D25) -> 327,78+127,53+0 | J31: 27 | K31: =180/PI()*ATAN(J31/100) -> 15.109575 | L31: =K31/180*PI() -> 0.26371183 | M31: =COS(K31*PI()/180) -> 0.96542908 | N31: =SIN(K31*PI()/180) -> 0.26066585 | O31: =TAN(K31*PI()/180) -> 0.27 | P31: FB= | Q31: =S31/S30*3.6*1000 -> 0 | R31: =R39-R38-R37-R34-R33-R32 -> 0 | S31: =S39-S38-S37-S34-S33-S32 -> 0
C32: FZ= | D32: =D17+D21+D25 -> 455.30778 | G32: 1 | J32: 28 | K32: =180/PI()*ATAN(J32/100) -> 15.642246 | L32: =K32/180*PI() -> 0.2730087 | M32: =COS(K32*PI()/180) -> 0.96296402 | N32: =SIN(K32*PI()/180) -> 0.26962993 | O32: =TAN(K32*PI()/180) -> 0.28 | P32: FLW= | Q32: =0.5*roh_Luft*cw*A*E12^2/3.6^2 -> 327.77778 | R32: =Q17*$R$15/3.6/1000 -> 9.1049383 | S32: =Q17*$S$15/3.6/1000 -> 9.1049383
H33: =SUM(G15:G32) -> 8 | J33: 29 | K33: =180/PI()*ATAN(J33/100) -> 16.172159 | L33: =K33/180*PI() -> 0.28225742 | M33: =COS(K33*PI()/180) -> 0.96042914 | N33: =SIN(K33*PI()/180) -> 0.27852445 | O33: =TAN(K33*PI()/180) -> 0.29 | P33: FR= | Q33: =m_F_normal*g_Erdbeschl.*fr -> 127.53 | R33: =Q33*$R$15/3.6/1000 -> 3.5425 | S33: =Q33*$S$15/3.6/1000 -> 3.5425
D34: λA = | E34: 0 | J34: 30 | K34: =180/PI()*ATAN(J34/100) -> 16.699244 | L34: =K34/180*PI() -> 0.29145679 | M34: =COS(K34*PI()/180) -> 0.95782629 | N34: =SIN(K34*PI()/180) -> 0.28734789 | O34: =TAN(K34*PI()/180) -> 0.3 | P34: FSt= | Q34: =m_F_normal*g_Erdbeschl.*p -> 0 | R34: =Q34*$R$15/3.6/1000 -> 0 | S34: =Q34*$S$15/3.6/1000 -> 0
A35: Aufgabe b) | J35: 31 | K35: =180/PI()*ATAN(J35/100) -> 17.223436 | L35: =K35/180*PI() -> 0.30060567 | M35: =COS(K35*PI()/180) -> 0.95515733 | N35: =SIN(K35*PI()/180) -> 0.29609877 | O35: =TAN(K35*PI()/180) -> 0.31 | P35: FZ= | Q35: =SUM(Q31:Q34) -> 455.30778
G36: 1 | J36: 32 | K36: =180/PI()*ATAN(J36/100) -> 17.744672 | L36: =K36/180*PI() -> 0.30970294 | M36: =COS(K36*PI()/180) -> 0.95242415 | N36: =SIN(K36*PI()/180) -> 0.30477573 | O36: =TAN(K36*PI()/180) -> 0.32
J37: 33 | K37: =180/PI()*ATAN(J37/100) -> 18.26289 | L37: =K37/180*PI() -> 0.31874756 | M37: =COS(K37*PI()/180) -> 0.94962865 | N37: =SIN(K37*PI()/180) -> 0.31337745 | O37: =TAN(K37*PI()/180) -> 0.33 | P37: FVT= | Q37: =R39*(1-eta_Tr)/V_F*3.6*1000 -> 29.062199 | R37: =Q37*$R$30/3.6/1000 -> 0.80728329 | S37: =R37 -> 0.80728329
G38: 2 | J38: 34 | K38: =180/PI()*ATAN(J38/100) -> 18.778033 | L38: =K38/180*PI() -> 0.32773851 | M38: =COS(K38*PI()/180) -> 0.94677274 | N38: =SIN(K38*PI()/180) -> 0.32190273 | O38: =TAN(K38*PI()/180) -> 0.34 | P38: FS= | Q38: =Q35*(v_th-V_F)/V_F -> 0 | R38: =D56 -> 0
J39: 35 | K39: =180/PI()*ATAN(J39/100) -> 19.290046 | L39: =K39/180*PI() -> 0.33667482 | M39: =COS(K39*PI()/180) -> 0.94385836 | N39: =SIN(K39*PI()/180) -> 0.33035042 | O39: =TAN(K39*PI()/180) -> 0.35 | R39: =D52 -> 13.454722 | S39: =D52 -> 13.454722
J40: 36 | K40: =180/PI()*ATAN(J40/100) -> 19.798876 | L40: =K40/180*PI() -> 0.34555558 | M40: =COS(K40*PI()/180) -> 0.94088741 | N40: =SIN(K40*PI()/180) -> 0.33871947 | O40: =TAN(K40*PI()/180) -> 0.36 | R40: =Q35+Q37+Q38 -> 484.36998 | S40: =Q35+Q37 -> 484.36998
B41: vth = | C41: =CONCATENATE(E12," / ","1-",LambdaA) -> 100 / 1-0 | J41: 37 | K41: =180/PI()*ATAN(J41/100) -> 20.304474 | L41: =K41/180*PI() -> 0.35437992 | M41: =COS(K41*PI()/180) -> 0.93786184 | N41: =SIN(K41*PI()/180) -> 0.34700888 | O41: =TAN(K41*PI()/180) -> 0.37
...

Sheet Getriebeauslegung
B1: n[rpm] | C1: P [kW] | D1: M [Nm]
B2: 1000 | C2: 3 | D2: =C2/B2*9554 -> 28.662
B3: 1200 | C3: 10 | D3: =C3/B3*9554 -> 79.616667
B4: 1400 | C4: 17 | D4: =C4/B4*9554 -> 116.01286
B5: 1600 | C5: 24 | D5: =C5/B5*9554 -> 143.31
B6: 1800 | C6: 30 | D6: =C6/B6*9554 -> 159.23333
B7: 2000 | C7: 36 | D7: =C7/B7*9554 -> 171.972
B8: 2200 | C8: 42 | D8: =C8/B8*9554 -> 182.39455
B9: 2400 | C9: 48 | D9: =C9/B9*9554 -> 191.08
B10: 2600 | C10: 54 | D10: =C10/B10*9554 -> 198.42923
B11: 2800 | C11: 60 | D11: =C11/B11*9554 -> 204.72857
B12: 3000 | C12: 66 | D12: =C12/B12*9554 -> 210.188
B13: 3200 | C13: 72 | D13: =C13/B13*9554 -> 214.965
... B25: 5600 | C25: 94 | D25: =C25/B25*9554 -> 160.37071
B26: 5800 | C26: 90 | D26: =C26/B26*9554 -> 148.25172 | L26: Feste Größen
L28: max. Steigf. | M28: 82.7 | N28: %
B29: Daten zur Diagrammdarstellung | L29: n max | M29: 5800 | N29: rpm
L30: r dyn | M30: 0.32 | N30: m
L31: i HA | M31: 3.18 | N31: -
B32: =E32 -> 0 | C32: =F32 -> 0 | E32: 0 | F32: 0 | H32: Untergrenze | I32: Obergrenze | L32: eta T | M32: 0.9 | N32: - | Q32: variable Größen
B33: =E33 -> 5800 | C33: =IF(F33=0,C35,F33) -> 45.810043 | E33: =IF(L51>0,$M$29,E35) -> 5800 | F33: =IF(L51>0,0.3768*$M$29*$M$30/($M$31*M51),0) -> 45.810043 | L33: fR | M33: 0.006 | N33: - | Q33: phi 2 | R33: 1.1 | S33: -
B34: =IF(F33=0,B36,C33*($M$31*M50)/0.3768/M30) -> 3004.8892 | C34: =IF(F33=0,C36,F33) -> 45.810043 | E34: 0 | F34: 0 | H34: =B34 -> 3004.8892 | I34: =E33 -> 5800 | J34: =C34 -> 45.810043 | L34: m F | M34: 1500 | N34: kg
B35: =E35 -> 5800 | C35: =IF(F35=0,C37,F35) -> 88.421978 | E35: =IF(L50>0,$M$29,E37) -> 5800 | F35: =IF(L50>0,0.3768*$M$29*$M$30/($M$31*M50),0) -> 88.421978 | H35: =B36 -> 3455.6226 | I35: =E35 -> 5800 | J35: =C35 -> 88.421978 | L35: Zuladung | M35: 0 | N35: kg
B36: =IF(F35=0,B38,C35*($M$31*M49)/0.3768/M30) -> 3455.6226 | C36: =IF(F35=0,C38,F35) -> 88.421978 | E36: 0 | F36: 0 | H36: =B38 -> 3973.966 | I36: =E37 -> 5800 | J36: =F37 -> 148.40957 | L36: M max | M36: 220 | N36: Nm
B37: =E37 -> 5800 | C37: =IF(F37=0,C39,F37) -> 148.40957 | E37: =$M$29 -> 5800 | F37: =IF(L49>0,0.3768*$M$29*$M$30/($M$31*M49),0) -> 148.40957 | H37: =B40 -> 4570.0609 | I37: =E39 -> 5800 | J37: =F39 -> 216.60364 | L37: =M42 -> 5 | M37: =I_5 -> 0.8
B38: =IF(F37=0,B40,C37*($M$31*M48)/0.3768/M30) -> 3973.966 | C38: =IF(F37=0,C40,F37) -> 148.40957 | E38: 0 | F38: 0 | H38: =B41 -> 5800 | I38: =E41 -> 5800 | J38: =F41 -> 274.89811
B39: =E39 -> 5800 | C39: =IF(F39=0,C41,F39) -> 216.60364 | E39: =$M$29 -> 5800 | F39: =0.3768*$M$29*$M$30/($M$31*M48) -> 216.60364 | I39: =E42 -> 0 | J39: =F42 -> 0
B40: =IF(F39=0,B42,C39*($M$31*$M$37)/0.3768/M30) -> 4570.0609 | C40: =IF(F39=0,C42,F39) -> 216.60364 | E40: 0 | F40: 0 | L40: variable Größen
B41: =E41 -> 5800 | C41: =F41 -> 274.89811 | E41: =$M$29 -> 5800 | F41: =0.3768*$M$29*$M$30/($M$31*M37) -> 274.89811 | L41: phi 2 | M41: 1.15 | N41: -
B42: =C41*($M$31*$M$37)/0.3768/M32 -> 2062.2222 | C42: =IF(F41=0,C44,F41) -> 274.89811 | E42: 0 | F42: 0 | I42: neu noch nicht aktualisiert | L42: Z | M42: 5 | N42: -
B43: =E43 -> 5800 | C43: =F43 -> #REF! | E43: =$M$29 -> 5800 | F43: =0.3768*$M$29*$M$30/($M$31*#REF!) -> #REF!
L45: Ergebnis
L46: i1 | M46: =((M34+M35)*9.81*(SIN(ATAN(M28/100))+M33*COS(ATAN(M28/100)))*M30/M32/M36)/M31 -> 4.8006611 | N46: -
L47: phi 1 | M47: =(I_1/phi_2^(0.5*(z_max-1)*(z_max-2))*(1/I_5))^(1/(z_max-1)) -> 1.2691297 | N47: -
L48: =M42-1 -> 4 | M48: =M47*M37 -> 1.0153038
L49: =M42-2 -> 3 | M49: =M47^2*M41*M37 -> 1.481835
L50: =M42-3 -> 2 | M50: =M47^3*M41^3*M37 -> 2.4871474
L51: =M42-4 -> 1 | M51: =M47^4*M41^6*M37 -> 4.8006611

Sheet 7 Schwerpunkt
A1: Aufgabe 8
A3: Ihr Fahrzeug bremst aus einer Geschwindigkeit von 100 km/h mit gleichmäßig innerhalb von 40m bis zum Stillstand ab. Der Angriffspunkt der Luftwiderstandskraft liegt 0,9 m hoch. a. Zeichnen Sie die für die Berechnung erforderlichen Kräfte und Längen in die Skizze ein. b. Berechnen sie die Beschleunigung des Fahrzeuges bei konstanter Bremsung. c. Bestimmen Sie nun die Achslasten bei konstanter linearer Bremsung (nehmen Sie hierbei für die Bestimmung der Luftwiderstandkraft eine konstanten Luftanströmgeschwindigkeit von 50km/h an).
A11: Gegeben:
A24: Aufgabe a) | G24: 4 | H24: Kräfte
G25: 3 | H25: Längen
G26: 2 | H26: Höhen
H28: 3
A32: Gegeben: | C32: hLW= | D32: 0.9 | E32: v0= | F32: 100
C33: hs= | D33: =hs -> 0.6 | E33: vLW_mittel= | F33: 50
C34: s= | D34: 40
A36: Aufgabe b) | B36: Bremsung
H38: 1
H42: 2
F44: a= | G44: =-0.5*(F32/3.6)^2/D34 -> -9.6450617 | H44: 1 | I44: =SUM(H35:H44) -> 4
A46: Aufgabe c) | H46: 1
F47: FB= | G47: =-m_F_normal*G44 -> 12538.58 | H47: 1
F49: FG = | G49: =(m_F_normal)*g_Erdbeschl. -> 12753 | H49: 1
F50: FLW = | G50: =0.5*roh_Luft*cw*A*(F33/3.6)^2 -> 81.944444 | H50: 1
H52: 2
H56: 1
B58: FNV= | C58: =CONCATENATE(1," / ",l_0," ( ",m_F_normal," * 9,81 * ",lh," + ",ROUND(G47,0)," * ",hs," - ",ROUND(G50,0)," * ",h_LW," ) =") -> 1 / 2,8 ( 1300 * 9,81 * 1,6 + 12539 * 0,6 - 82 * 0,9 ) = | G58: =1/l_0*(m_F_normal*g_Erdbeschl.*lh+G47*D33-G50*h_LW) -> 9947.9279 | H58: 1
H60: 1
D61: FNh= | E61: =CONCATENATE(ROUND(G_normal_Gewichtskr.,0)," - ",ROUND(G58,0)," = ") -> 12753 - 9948 = | G61: =G_normal_Gewichtskr.-G58 -> 2805.0721 | H61: 1
I62: =SUM(H46:H61) -> 10
A63: Alternativ
B68: =CONCATENATE("=",1,"/",l_0,"(",m_F_normal,"*9,81*",lv,"-",ROUND(G47,0),"*",hs,"+",ROUND(G50,0),"*",h_LW,,")") -> #NAME?
F69: FNh= | G69: =1/l_0*(m_F_normal*g_Erdbeschl.*lv-G47*hs+G50*h_LW) -> #NAME?
F70: Summe= | G70: =SUM(G58,G69) -> #NAME?
G74: Summe: | H74: =SUM(H27:H61) -> 17

Sheet 3 Getriebe
A1: Aufgabe 3
A3: Gegeben ist ein Fünfganggetriebe mit einer Spreizung von 5,5. Die Übersetzung im 1. Gang beträgt 4,4. Bestimmen Sie die Übersetzungen in den Gängen 2 bis 5 bei einer geometrischen Getriebeauslegung.
A6: Aufgabe a) | C6: gegeben: | D6: Spreizung = | E6: 5.5 | F6: z= | G6: 5
D7: i1= | E7: =I_1 -> 4.8006611
G9: 1
G11: 1
E13: i5= | F13: =I_1/i_Gges -> #NAME? | G13: 1 | I13: i5= | J13: =I_1/i_Gges -> #NAME?
G15: 1
E17: ρ𝑡ℎ= | F17: =(I_1/F13)^(1/(G6-1)) -> #NAME? | G17: 1
G19: 1 | J19: =F13/F17 -> #NAME?
E23: i2 = | F23: =F13*F17^(G6-2) -> #NAME? | G23: 1
E24: i3 = | F24: =F13*F17^(G6-3) -> #NAME? | G24: 1
E25: i4 = | F25: =F13*F17^(G6-4) -> #NAME? | G25: 1 | I25: i5 = | J25: =J13*J17^(K6-4) -> #NAME?
G27: =SUM(G7:G25) -> 9
